
2015-12-09 18:27:59,155:

Hello,

Sorry to tell you that it seems something is wrong on the MindTrails data collecting server, and below is the error message:

2015-12-09 18:27:59,155 export.safeRequest CRITICAL Data request failed, fatal, emailed admin. see below for error information:

Hope that you are not sleeping now. Please check it up immediately!

Your faithfully,
Mindtrails Android
Martin

Exception Information:
Traceback (most recent call last):
  File "export.py", line 76, in safeRequest
    response = requests.get(url, auth=(USER,PASS))
  File "/Users/Diheng/PIExporter/venv/lib/python2.7/site-packages/requests/api.py", line 69, in get
    return request('get', url, params=params, **kwargs)
  File "/Users/Diheng/PIExporter/venv/lib/python2.7/site-packages/requests/api.py", line 50, in request
    response = session.request(method=method, url=url, **kwargs)
  File "/Users/Diheng/PIExporter/venv/lib/python2.7/site-packages/requests/sessions.py", line 468, in request
    resp = self.send(prep, **send_kwargs)
  File "/Users/Diheng/PIExporter/venv/lib/python2.7/site-packages/requests/sessions.py", line 576, in send
    r = adapter.send(request, **kwargs)
  File "/Users/Diheng/PIExporter/venv/lib/python2.7/site-packages/requests/adapters.py", line 423, in send
    raise ConnectionError(e, request=request)
ConnectionError: HTTPConnectionPool(host='localhost', port=9000): Max retries exceeded with url: /api/export (Caused by NewConnectionError('<requests.packages.urllib3.connection.HTTPConnection object at 0x10b4c36d0>: Failed to establish a new connection: [Errno 61] Connection refused',))
