
2015-12-11 16:18:55,020:

Hello,

Sorry to tell you that it seems something is wrong on the MindTrails data collecting server, and below is the error message:

2015-12-11 16:18:55,020 export.safeKeep CRITICAL MultiUserExperience data backup failed, immediate attention needed.

Hope that you are not sleeping now. Please check it up immediately!

Your faithfully,
Mindtrails Android
Martin

Exception Information:
Traceback (most recent call last):
  File "export.py", line 66, in safeKeep
    db = shelve.open(file)
  File "/System/Library/Frameworks/Python.framework/Versions/2.7/lib/python2.7/shelve.py", line 243, in open
    return DbfilenameShelf(filename, flag, protocol, writeback)
  File "/System/Library/Frameworks/Python.framework/Versions/2.7/lib/python2.7/shelve.py", line 227, in __init__
    Shelf.__init__(self, anydbm.open(filename, flag), protocol, writeback)
  File "/System/Library/Frameworks/Python.framework/Versions/2.7/lib/python2.7/anydbm.py", line 85, in open
    return mod.open(file, flag, mode)
error: (2, 'No such file or directory')

2015-12-11 16:18:57,822:

Hello,

Sorry to tell you that it seems something is wrong on the MindTrails data collecting server, and below is the error message:

2015-12-11 16:18:57,822 export.safeKeep CRITICAL CC data backup failed, immediate attention needed.

Hope that you are not sleeping now. Please check it up immediately!

Your faithfully,
Mindtrails Android
Martin

Exception Information:
Traceback (most recent call last):
  File "export.py", line 66, in safeKeep
    db = shelve.open(file)
  File "/System/Library/Frameworks/Python.framework/Versions/2.7/lib/python2.7/shelve.py", line 243, in open
    return DbfilenameShelf(filename, flag, protocol, writeback)
  File "/System/Library/Frameworks/Python.framework/Versions/2.7/lib/python2.7/shelve.py", line 227, in __init__
    Shelf.__init__(self, anydbm.open(filename, flag), protocol, writeback)
  File "/System/Library/Frameworks/Python.framework/Versions/2.7/lib/python2.7/anydbm.py", line 85, in open
    return mod.open(file, flag, mode)
error: (2, 'No such file or directory')

2015-12-11 16:18:59,823:

Hello,

Sorry to tell you that it seems something is wrong on the MindTrails data collecting server, and below is the error message:

2015-12-11 16:18:59,823 export.safeKeep CRITICAL BBSIQ data backup failed, immediate attention needed.

Hope that you are not sleeping now. Please check it up immediately!

Your faithfully,
Mindtrails Android
Martin

Exception Information:
Traceback (most recent call last):
  File "export.py", line 66, in safeKeep
    db = shelve.open(file)
  File "/System/Library/Frameworks/Python.framework/Versions/2.7/lib/python2.7/shelve.py", line 243, in open
    return DbfilenameShelf(filename, flag, protocol, writeback)
  File "/System/Library/Frameworks/Python.framework/Versions/2.7/lib/python2.7/shelve.py", line 227, in __init__
    Shelf.__init__(self, anydbm.open(filename, flag), protocol, writeback)
  File "/System/Library/Frameworks/Python.framework/Versions/2.7/lib/python2.7/anydbm.py", line 85, in open
    return mod.open(file, flag, mode)
error: (2, 'No such file or directory')

2015-12-11 16:19:01,370:

Hello,

Sorry to tell you that it seems something is wrong on the MindTrails data collecting server, and below is the error message:

2015-12-11 16:19:01,370 export.safeKeep CRITICAL DASS21_DS data backup failed, immediate attention needed.

Hope that you are not sleeping now. Please check it up immediately!

Your faithfully,
Mindtrails Android
Martin

Exception Information:
Traceback (most recent call last):
  File "export.py", line 66, in safeKeep
    db = shelve.open(file)
  File "/System/Library/Frameworks/Python.framework/Versions/2.7/lib/python2.7/shelve.py", line 243, in open
    return DbfilenameShelf(filename, flag, protocol, writeback)
  File "/System/Library/Frameworks/Python.framework/Versions/2.7/lib/python2.7/shelve.py", line 227, in __init__
    Shelf.__init__(self, anydbm.open(filename, flag), protocol, writeback)
  File "/System/Library/Frameworks/Python.framework/Versions/2.7/lib/python2.7/anydbm.py", line 85, in open
    return mod.open(file, flag, mode)
error: (2, 'No such file or directory')

2015-12-11 16:19:02,662:

Hello,

Sorry to tell you that it seems something is wrong on the MindTrails data collecting server, and below is the error message:

2015-12-11 16:19:02,662 export.safeKeep CRITICAL QOL data backup failed, immediate attention needed.

Hope that you are not sleeping now. Please check it up immediately!

Your faithfully,
Mindtrails Android
Martin

Exception Information:
Traceback (most recent call last):
  File "export.py", line 66, in safeKeep
    db = shelve.open(file)
  File "/System/Library/Frameworks/Python.framework/Versions/2.7/lib/python2.7/shelve.py", line 243, in open
    return DbfilenameShelf(filename, flag, protocol, writeback)
  File "/System/Library/Frameworks/Python.framework/Versions/2.7/lib/python2.7/shelve.py", line 227, in __init__
    Shelf.__init__(self, anydbm.open(filename, flag), protocol, writeback)
  File "/System/Library/Frameworks/Python.framework/Versions/2.7/lib/python2.7/anydbm.py", line 85, in open
    return mod.open(file, flag, mode)
error: (2, 'No such file or directory')

2015-12-11 16:19:04,880:

Hello,

Sorry to tell you that it seems something is wrong on the MindTrails data collecting server, and below is the error message:

2015-12-11 16:19:04,880 export.safeKeep CRITICAL OA data backup failed, immediate attention needed.

Hope that you are not sleeping now. Please check it up immediately!

Your faithfully,
Mindtrails Android
Martin

Exception Information:
Traceback (most recent call last):
  File "export.py", line 66, in safeKeep
    db = shelve.open(file)
  File "/System/Library/Frameworks/Python.framework/Versions/2.7/lib/python2.7/shelve.py", line 243, in open
    return DbfilenameShelf(filename, flag, protocol, writeback)
  File "/System/Library/Frameworks/Python.framework/Versions/2.7/lib/python2.7/shelve.py", line 227, in __init__
    Shelf.__init__(self, anydbm.open(filename, flag), protocol, writeback)
  File "/System/Library/Frameworks/Python.framework/Versions/2.7/lib/python2.7/anydbm.py", line 85, in open
    return mod.open(file, flag, mode)
error: (2, 'No such file or directory')

2015-12-11 16:19:06,329:

Hello,

Sorry to tell you that it seems something is wrong on the MindTrails data collecting server, and below is the error message:

2015-12-11 16:19:06,329 export.safeKeep CRITICAL RR data backup failed, immediate attention needed.

Hope that you are not sleeping now. Please check it up immediately!

Your faithfully,
Mindtrails Android
Martin

Exception Information:
Traceback (most recent call last):
  File "export.py", line 66, in safeKeep
    db = shelve.open(file)
  File "/System/Library/Frameworks/Python.framework/Versions/2.7/lib/python2.7/shelve.py", line 243, in open
    return DbfilenameShelf(filename, flag, protocol, writeback)
  File "/System/Library/Frameworks/Python.framework/Versions/2.7/lib/python2.7/shelve.py", line 227, in __init__
    Shelf.__init__(self, anydbm.open(filename, flag), protocol, writeback)
  File "/System/Library/Frameworks/Python.framework/Versions/2.7/lib/python2.7/anydbm.py", line 85, in open
    return mod.open(file, flag, mode)
error: (2, 'No such file or directory')

2015-12-11 16:19:08,306:

Hello,

Sorry to tell you that it seems something is wrong on the MindTrails data collecting server, and below is the error message:

2015-12-11 16:19:08,306 export.safeKeep CRITICAL ImpactAnxiousImagery data backup failed, immediate attention needed.

Hope that you are not sleeping now. Please check it up immediately!

Your faithfully,
Mindtrails Android
Martin

Exception Information:
Traceback (most recent call last):
  File "export.py", line 66, in safeKeep
    db = shelve.open(file)
  File "/System/Library/Frameworks/Python.framework/Versions/2.7/lib/python2.7/shelve.py", line 243, in open
    return DbfilenameShelf(filename, flag, protocol, writeback)
  File "/System/Library/Frameworks/Python.framework/Versions/2.7/lib/python2.7/shelve.py", line 227, in __init__
    Shelf.__init__(self, anydbm.open(filename, flag), protocol, writeback)
  File "/System/Library/Frameworks/Python.framework/Versions/2.7/lib/python2.7/anydbm.py", line 85, in open
    return mod.open(file, flag, mode)
error: (2, 'No such file or directory')

2015-12-11 16:19:09,652:

Hello,

Sorry to tell you that it seems something is wrong on the MindTrails data collecting server, and below is the error message:

2015-12-11 16:19:09,652 export.safeKeep CRITICAL SUDS data backup failed, immediate attention needed.

Hope that you are not sleeping now. Please check it up immediately!

Your faithfully,
Mindtrails Android
Martin

Exception Information:
Traceback (most recent call last):
  File "export.py", line 66, in safeKeep
    db = shelve.open(file)
  File "/System/Library/Frameworks/Python.framework/Versions/2.7/lib/python2.7/shelve.py", line 243, in open
    return DbfilenameShelf(filename, flag, protocol, writeback)
  File "/System/Library/Frameworks/Python.framework/Versions/2.7/lib/python2.7/shelve.py", line 227, in __init__
    Shelf.__init__(self, anydbm.open(filename, flag), protocol, writeback)
  File "/System/Library/Frameworks/Python.framework/Versions/2.7/lib/python2.7/anydbm.py", line 85, in open
    return mod.open(file, flag, mode)
error: (2, 'No such file or directory')

2015-12-11 16:19:11,167:

Hello,

Sorry to tell you that it seems something is wrong on the MindTrails data collecting server, and below is the error message:

2015-12-11 16:19:11,167 export.safeKeep CRITICAL AnxietyTriggers data backup failed, immediate attention needed.

Hope that you are not sleeping now. Please check it up immediately!

Your faithfully,
Mindtrails Android
Martin

Exception Information:
Traceback (most recent call last):
  File "export.py", line 66, in safeKeep
    db = shelve.open(file)
  File "/System/Library/Frameworks/Python.framework/Versions/2.7/lib/python2.7/shelve.py", line 243, in open
    return DbfilenameShelf(filename, flag, protocol, writeback)
  File "/System/Library/Frameworks/Python.framework/Versions/2.7/lib/python2.7/shelve.py", line 227, in __init__
    Shelf.__init__(self, anydbm.open(filename, flag), protocol, writeback)
  File "/System/Library/Frameworks/Python.framework/Versions/2.7/lib/python2.7/anydbm.py", line 85, in open
    return mod.open(file, flag, mode)
error: (2, 'No such file or directory')

2015-12-11 16:19:12,845:

Hello,

Sorry to tell you that it seems something is wrong on the MindTrails data collecting server, and below is the error message:

2015-12-11 16:19:12,845 export.safeKeep CRITICAL DD data backup failed, immediate attention needed.

Hope that you are not sleeping now. Please check it up immediately!

Your faithfully,
Mindtrails Android
Martin

Exception Information:
Traceback (most recent call last):
  File "export.py", line 66, in safeKeep
    db = shelve.open(file)
  File "/System/Library/Frameworks/Python.framework/Versions/2.7/lib/python2.7/shelve.py", line 243, in open
    return DbfilenameShelf(filename, flag, protocol, writeback)
  File "/System/Library/Frameworks/Python.framework/Versions/2.7/lib/python2.7/shelve.py", line 227, in __init__
    Shelf.__init__(self, anydbm.open(filename, flag), protocol, writeback)
  File "/System/Library/Frameworks/Python.framework/Versions/2.7/lib/python2.7/anydbm.py", line 85, in open
    return mod.open(file, flag, mode)
error: (2, 'No such file or directory')

2015-12-11 16:19:14,201:

Hello,

Sorry to tell you that it seems something is wrong on the MindTrails data collecting server, and below is the error message:

2015-12-11 16:19:14,201 export.safeKeep CRITICAL Credibility data backup failed, immediate attention needed.

Hope that you are not sleeping now. Please check it up immediately!

Your faithfully,
Mindtrails Android
Martin

Exception Information:
Traceback (most recent call last):
  File "export.py", line 66, in safeKeep
    db = shelve.open(file)
  File "/System/Library/Frameworks/Python.framework/Versions/2.7/lib/python2.7/shelve.py", line 243, in open
    return DbfilenameShelf(filename, flag, protocol, writeback)
  File "/System/Library/Frameworks/Python.framework/Versions/2.7/lib/python2.7/shelve.py", line 227, in __init__
    Shelf.__init__(self, anydbm.open(filename, flag), protocol, writeback)
  File "/System/Library/Frameworks/Python.framework/Versions/2.7/lib/python2.7/anydbm.py", line 85, in open
    return mod.open(file, flag, mode)
error: (2, 'No such file or directory')

2015-12-11 16:19:16,030:

Hello,

Sorry to tell you that it seems something is wrong on the MindTrails data collecting server, and below is the error message:

2015-12-11 16:19:16,030 export.safeKeep CRITICAL MentalHealthHxTx data backup failed, immediate attention needed.

Hope that you are not sleeping now. Please check it up immediately!

Your faithfully,
Mindtrails Android
Martin

Exception Information:
Traceback (most recent call last):
  File "export.py", line 66, in safeKeep
    db = shelve.open(file)
  File "/System/Library/Frameworks/Python.framework/Versions/2.7/lib/python2.7/shelve.py", line 243, in open
    return DbfilenameShelf(filename, flag, protocol, writeback)
  File "/System/Library/Frameworks/Python.framework/Versions/2.7/lib/python2.7/shelve.py", line 227, in __init__
    Shelf.__init__(self, anydbm.open(filename, flag), protocol, writeback)
  File "/System/Library/Frameworks/Python.framework/Versions/2.7/lib/python2.7/anydbm.py", line 85, in open
    return mod.open(file, flag, mode)
error: (2, 'No such file or directory')

2015-12-11 16:19:17,883:

Hello,

Sorry to tell you that it seems something is wrong on the MindTrails data collecting server, and below is the error message:

2015-12-11 16:19:17,883 export.safeKeep CRITICAL ImageryPrime data backup failed, immediate attention needed.

Hope that you are not sleeping now. Please check it up immediately!

Your faithfully,
Mindtrails Android
Martin

Exception Information:
Traceback (most recent call last):
  File "export.py", line 66, in safeKeep
    db = shelve.open(file)
  File "/System/Library/Frameworks/Python.framework/Versions/2.7/lib/python2.7/shelve.py", line 243, in open
    return DbfilenameShelf(filename, flag, protocol, writeback)
  File "/System/Library/Frameworks/Python.framework/Versions/2.7/lib/python2.7/shelve.py", line 227, in __init__
    Shelf.__init__(self, anydbm.open(filename, flag), protocol, writeback)
  File "/System/Library/Frameworks/Python.framework/Versions/2.7/lib/python2.7/anydbm.py", line 85, in open
    return mod.open(file, flag, mode)
error: (2, 'No such file or directory')

2015-12-11 16:19:19,691:

Hello,

Sorry to tell you that it seems something is wrong on the MindTrails data collecting server, and below is the error message:

2015-12-11 16:19:19,691 export.safeKeep CRITICAL ReasonsForEnding data backup failed, immediate attention needed.

Hope that you are not sleeping now. Please check it up immediately!

Your faithfully,
Mindtrails Android
Martin

Exception Information:
Traceback (most recent call last):
  File "export.py", line 66, in safeKeep
    db = shelve.open(file)
  File "/System/Library/Frameworks/Python.framework/Versions/2.7/lib/python2.7/shelve.py", line 243, in open
    return DbfilenameShelf(filename, flag, protocol, writeback)
  File "/System/Library/Frameworks/Python.framework/Versions/2.7/lib/python2.7/shelve.py", line 227, in __init__
    Shelf.__init__(self, anydbm.open(filename, flag), protocol, writeback)
  File "/System/Library/Frameworks/Python.framework/Versions/2.7/lib/python2.7/anydbm.py", line 85, in open
    return mod.open(file, flag, mode)
error: (2, 'No such file or directory')

2015-12-11 16:19:21,072:

Hello,

Sorry to tell you that it seems something is wrong on the MindTrails data collecting server, and below is the error message:

2015-12-11 16:19:21,072 export.safeKeep CRITICAL Demographic data backup failed, immediate attention needed.

Hope that you are not sleeping now. Please check it up immediately!

Your faithfully,
Mindtrails Android
Martin

Exception Information:
Traceback (most recent call last):
  File "export.py", line 66, in safeKeep
    db = shelve.open(file)
  File "/System/Library/Frameworks/Python.framework/Versions/2.7/lib/python2.7/shelve.py", line 243, in open
    return DbfilenameShelf(filename, flag, protocol, writeback)
  File "/System/Library/Frameworks/Python.framework/Versions/2.7/lib/python2.7/shelve.py", line 227, in __init__
    Shelf.__init__(self, anydbm.open(filename, flag), protocol, writeback)
  File "/System/Library/Frameworks/Python.framework/Versions/2.7/lib/python2.7/anydbm.py", line 85, in open
    return mod.open(file, flag, mode)
error: (2, 'No such file or directory')

2015-12-11 16:19:22,459:

Hello,

Sorry to tell you that it seems something is wrong on the MindTrails data collecting server, and below is the error message:

2015-12-11 16:19:22,459 export.safeKeep CRITICAL CIHS data backup failed, immediate attention needed.

Hope that you are not sleeping now. Please check it up immediately!

Your faithfully,
Mindtrails Android
Martin

Exception Information:
Traceback (most recent call last):
  File "export.py", line 66, in safeKeep
    db = shelve.open(file)
  File "/System/Library/Frameworks/Python.framework/Versions/2.7/lib/python2.7/shelve.py", line 243, in open
    return DbfilenameShelf(filename, flag, protocol, writeback)
  File "/System/Library/Frameworks/Python.framework/Versions/2.7/lib/python2.7/shelve.py", line 227, in __init__
    Shelf.__init__(self, anydbm.open(filename, flag), protocol, writeback)
  File "/System/Library/Frameworks/Python.framework/Versions/2.7/lib/python2.7/anydbm.py", line 85, in open
    return mod.open(file, flag, mode)
error: (2, 'No such file or directory')

2015-12-11 16:19:24,223:

Hello,

Sorry to tell you that it seems something is wrong on the MindTrails data collecting server, and below is the error message:

2015-12-11 16:19:24,223 export.safeKeep CRITICAL DASS21_AS data backup failed, immediate attention needed.

Hope that you are not sleeping now. Please check it up immediately!

Your faithfully,
Mindtrails Android
Martin

Exception Information:
Traceback (most recent call last):
  File "export.py", line 66, in safeKeep
    db = shelve.open(file)
  File "/System/Library/Frameworks/Python.framework/Versions/2.7/lib/python2.7/shelve.py", line 243, in open
    return DbfilenameShelf(filename, flag, protocol, writeback)
  File "/System/Library/Frameworks/Python.framework/Versions/2.7/lib/python2.7/shelve.py", line 227, in __init__
    Shelf.__init__(self, anydbm.open(filename, flag), protocol, writeback)
  File "/System/Library/Frameworks/Python.framework/Versions/2.7/lib/python2.7/anydbm.py", line 85, in open
    return mod.open(file, flag, mode)
error: (2, 'No such file or directory')

2015-12-11 16:19:25,612:

Hello,

Sorry to tell you that it seems something is wrong on the MindTrails data collecting server, and below is the error message:

2015-12-11 16:19:25,612 export.safeKeep CRITICAL DD_FU data backup failed, immediate attention needed.

Hope that you are not sleeping now. Please check it up immediately!

Your faithfully,
Mindtrails Android
Martin

Exception Information:
Traceback (most recent call last):
  File "export.py", line 66, in safeKeep
    db = shelve.open(file)
  File "/System/Library/Frameworks/Python.framework/Versions/2.7/lib/python2.7/shelve.py", line 243, in open
    return DbfilenameShelf(filename, flag, protocol, writeback)
  File "/System/Library/Frameworks/Python.framework/Versions/2.7/lib/python2.7/shelve.py", line 227, in __init__
    Shelf.__init__(self, anydbm.open(filename, flag), protocol, writeback)
  File "/System/Library/Frameworks/Python.framework/Versions/2.7/lib/python2.7/anydbm.py", line 85, in open
    return mod.open(file, flag, mode)
error: (2, 'No such file or directory')

2015-12-11 17:20:56,829:

Hello,

Sorry to tell you that it seems something is wrong on the MindTrails data collecting server, and below is the error message:

2015-12-11 17:20:56,829 export.safeDelete CRITICAL Data delete failed, fatal, emailed admin. see below for error information:

Hope that you are not sleeping now. Please check it up immediately!

Your faithfully,
Mindtrails Android
Martin

Exception Information:
Traceback (most recent call last):
  File "export.py", line 98, in safeDelete
    m = delete.raise_for_status()
  File "/Users/Diheng/PIExporter/venv/lib/python2.7/site-packages/requests/models.py", line 837, in raise_for_status
    raise HTTPError(http_error_msg, response=self)
HTTPError: 500 Server Error: Internal Server Error for url: http://localhost:9000/api/export/MentalHealthHxTx/1

2015-12-11 17:21:03,552:

Hello,

Sorry to tell you that it seems something is wrong on the MindTrails data collecting server, and below is the error message:

2015-12-11 17:21:03,552 export.safeDelete CRITICAL Data delete failed, fatal, emailed admin. see below for error information:

Hope that you are not sleeping now. Please check it up immediately!

Your faithfully,
Mindtrails Android
Martin

Exception Information:
Traceback (most recent call last):
  File "export.py", line 98, in safeDelete
    m = delete.raise_for_status()
  File "/Users/Diheng/PIExporter/venv/lib/python2.7/site-packages/requests/models.py", line 837, in raise_for_status
    raise HTTPError(http_error_msg, response=self)
HTTPError: 500 Server Error: Internal Server Error for url: http://localhost:9000/api/export/MentalHealthHxTx/2

2015-12-11 17:31:20,638:

Hello,

Sorry to tell you that it seems something is wrong on the MindTrails data collecting server, and below is the error message:

2015-12-11 17:31:20,638 export.safeDelete CRITICAL Data delete failed, fatal, emailed admin. see below for error information:

Hope that you are not sleeping now. Please check it up immediately!

Your faithfully,
Mindtrails Android
Martin

Exception Information:
Traceback (most recent call last):
  File "export.py", line 100, in safeDelete
    m = delete.raise_for_status()
  File "/Users/Diheng/PIExporter/venv/lib/python2.7/site-packages/requests/models.py", line 837, in raise_for_status
    raise HTTPError(http_error_msg, response=self)
HTTPError: 500 Server Error: Internal Server Error for url: http://localhost:9000/api/export/MentalHealthHxTx/1

2015-12-11 17:31:23,552:

Hello,

Sorry to tell you that it seems something is wrong on the MindTrails data collecting server, and below is the error message:

2015-12-11 17:31:23,552 export.safeDelete CRITICAL Data delete failed, fatal, emailed admin. see below for error information:

Hope that you are not sleeping now. Please check it up immediately!

Your faithfully,
Mindtrails Android
Martin

Exception Information:
Traceback (most recent call last):
  File "export.py", line 100, in safeDelete
    m = delete.raise_for_status()
  File "/Users/Diheng/PIExporter/venv/lib/python2.7/site-packages/requests/models.py", line 837, in raise_for_status
    raise HTTPError(http_error_msg, response=self)
HTTPError: 500 Server Error: Internal Server Error for url: http://localhost:9000/api/export/MentalHealthHxTx/2

2015-12-11 17:31:35,819:

Hello,

Sorry to tell you that it seems something is wrong on the MindTrails data collecting server, and below is the error message:

2015-12-11 17:31:35,819 export.safeDelete CRITICAL Data delete failed, fatal, emailed admin. see below for error information:

Hope that you are not sleeping now. Please check it up immediately!

Your faithfully,
Mindtrails Android
Martin

Exception Information:
Traceback (most recent call last):
  File "export.py", line 100, in safeDelete
    m = delete.raise_for_status()
  File "/Users/Diheng/PIExporter/venv/lib/python2.7/site-packages/requests/models.py", line 837, in raise_for_status
    raise HTTPError(http_error_msg, response=self)
HTTPError: 500 Server Error: Internal Server Error for url: http://localhost:9000/api/export/MentalHealthHxTx/1

2015-12-11 17:31:37,010:

Hello,

Sorry to tell you that it seems something is wrong on the MindTrails data collecting server, and below is the error message:

2015-12-11 17:31:37,010 export.safeDelete CRITICAL Data delete failed, fatal, emailed admin. see below for error information:

Hope that you are not sleeping now. Please check it up immediately!

Your faithfully,
Mindtrails Android
Martin

Exception Information:
Traceback (most recent call last):
  File "export.py", line 100, in safeDelete
    m = delete.raise_for_status()
  File "/Users/Diheng/PIExporter/venv/lib/python2.7/site-packages/requests/models.py", line 837, in raise_for_status
    raise HTTPError(http_error_msg, response=self)
HTTPError: 500 Server Error: Internal Server Error for url: http://localhost:9000/api/export/MentalHealthHxTx/2

2015-12-11 17:31:42,229:

Hello,

Sorry to tell you that it seems something is wrong on the MindTrails data collecting server, and below is the error message:

2015-12-11 17:31:42,229 export.safeDelete CRITICAL Data delete failed, fatal, emailed admin. see below for error information:

Hope that you are not sleeping now. Please check it up immediately!

Your faithfully,
Mindtrails Android
Martin

Exception Information:
Traceback (most recent call last):
  File "export.py", line 100, in safeDelete
    m = delete.raise_for_status()
  File "/Users/Diheng/PIExporter/venv/lib/python2.7/site-packages/requests/models.py", line 837, in raise_for_status
    raise HTTPError(http_error_msg, response=self)
HTTPError: 500 Server Error: Internal Server Error for url: http://localhost:9000/api/export/MentalHealthHxTx/1

2015-12-11 17:31:43,610:

Hello,

Sorry to tell you that it seems something is wrong on the MindTrails data collecting server, and below is the error message:

2015-12-11 17:31:43,610 export.safeDelete CRITICAL Data delete failed, fatal, emailed admin. see below for error information:

Hope that you are not sleeping now. Please check it up immediately!

Your faithfully,
Mindtrails Android
Martin

Exception Information:
Traceback (most recent call last):
  File "export.py", line 100, in safeDelete
    m = delete.raise_for_status()
  File "/Users/Diheng/PIExporter/venv/lib/python2.7/site-packages/requests/models.py", line 837, in raise_for_status
    raise HTTPError(http_error_msg, response=self)
HTTPError: 500 Server Error: Internal Server Error for url: http://localhost:9000/api/export/MentalHealthHxTx/2

2015-12-11 17:41:08,172:

Hello,

Sorry to tell you that it seems something is wrong on the MindTrails data collecting server, and below is the error message:

2015-12-11 17:41:08,172 export.safeDelete CRITICAL Data delete failed, fatal, emailed admin. see below for error information:

Hope that you are not sleeping now. Please check it up immediately!

Your faithfully,
Mindtrails Android
Martin

Exception Information:
Traceback (most recent call last):
  File "export.py", line 100, in safeDelete
    m = delete.raise_for_status()
  File "/Users/Diheng/PIExporter/venv/lib/python2.7/site-packages/requests/models.py", line 837, in raise_for_status
    raise HTTPError(http_error_msg, response=self)
HTTPError: 500 Server Error: Internal Server Error for url: http://localhost:9000/api/export/MentalHealthHxTx/1

2015-12-11 17:41:11,206:

Hello,

Sorry to tell you that it seems something is wrong on the MindTrails data collecting server, and below is the error message:

2015-12-11 17:41:11,206 export.safeDelete CRITICAL Data delete failed, fatal, emailed admin. see below for error information:

Hope that you are not sleeping now. Please check it up immediately!

Your faithfully,
Mindtrails Android
Martin

Exception Information:
Traceback (most recent call last):
  File "export.py", line 100, in safeDelete
    m = delete.raise_for_status()
  File "/Users/Diheng/PIExporter/venv/lib/python2.7/site-packages/requests/models.py", line 837, in raise_for_status
    raise HTTPError(http_error_msg, response=self)
HTTPError: 500 Server Error: Internal Server Error for url: http://localhost:9000/api/export/MentalHealthHxTx/2

2015-12-11 17:45:59,890:

Hello,

Sorry to tell you that it seems something is wrong on the MindTrails data collecting server, and below is the error message:

2015-12-11 17:45:59,890 export.safeDelete CRITICAL Data delete failed, fatal, emailed admin. see below for error information:

Hope that you are not sleeping now. Please check it up immediately!

Your faithfully,
Mindtrails Android
Martin

Exception Information:
Traceback (most recent call last):
  File "export.py", line 100, in safeDelete
    m = delete.raise_for_status()
  File "/Users/Diheng/PIExporter/venv/lib/python2.7/site-packages/requests/models.py", line 837, in raise_for_status
    raise HTTPError(http_error_msg, response=self)
HTTPError: 500 Server Error: Internal Server Error for url: http://localhost:9000/api/export/MentalHealthHxTx/1

2015-12-11 17:46:02,196:

Hello,

Sorry to tell you that it seems something is wrong on the MindTrails data collecting server, and below is the error message:

2015-12-11 17:46:02,196 export.safeDelete CRITICAL Data delete failed, fatal, emailed admin. see below for error information:

Hope that you are not sleeping now. Please check it up immediately!

Your faithfully,
Mindtrails Android
Martin

Exception Information:
Traceback (most recent call last):
  File "export.py", line 100, in safeDelete
    m = delete.raise_for_status()
  File "/Users/Diheng/PIExporter/venv/lib/python2.7/site-packages/requests/models.py", line 837, in raise_for_status
    raise HTTPError(http_error_msg, response=self)
HTTPError: 500 Server Error: Internal Server Error for url: http://localhost:9000/api/export/MentalHealthHxTx/2
